<?xml version="1.0" encoding="UTF-8"?>
<!-- Generated by org.testng.reporters.JUnitReportReporter -->
<testsuite name="com.TestNGproject.TestNGAssertsDemo" tests="3" time="0.050" ignored="0" failures="1" timestamp="18 Mar 2021 03:33:15 GMT" skipped="0" hostname="DESKTOP-9U807NB" errors="0">
  <testcase name="testMethod3" time="0.005" classname="com.TestNGproject.TestNGAssertsDemo"/>
  <testcase name="testMethod2" time="0.043" classname="com.TestNGproject.TestNGAssertsDemo">
    <failure type="java.lang.AssertionError" message="The following asserts failed:
	expected [3] but found [4]">
      <![CDATA[java.lang.AssertionError: The following asserts failed:
	expected [3] but found [4]
	at org.testng.asserts.SoftAssert.assertAll(SoftAssert.java:43)
	at com.TestNGproject.TestNGAssertsDemo.testMethod2(TestNGAssertsDemo.java:36)
	at sun.reflect.NativeMethodAccessorImpl.invoke0(Native Method)
	at sun.reflect.NativeMethodAccessorImpl.invoke(NativeMethodAccessorImpl.java:62)
	at sun.reflect.DelegatingMethodAccessorImpl.invoke(DelegatingMethodAccessorImpl.java:43)
	at java.lang.reflect.Method.invoke(Method.java:498)
	at org.testng.internal.MethodInvocationHelper.invokeMethod(MethodInvocationHelper.java:104)
	at org.testng.internal.Invoker.invokeMethod(Invoker.java:645)
	at org.testng.internal.Invoker.invokeTestMethod(Invoker.java:851)
	at org.testng.internal.Invoker.invokeTestMethods(Invoker.java:1177)
	at org.testng.internal.TestMethodWorker.invokeTestMethods(TestMethodWorker.java:129)
	at org.testng.internal.TestMethodWorker.run(TestMethodWorker.java:112)
	at org.testng.TestRunner.privateRun(TestRunner.java:756)
	at org.testng.TestRunner.run(TestRunner.java:610)
	at org.testng.SuiteRunner.runTest(SuiteRunner.java:387)
	at org.testng.SuiteRunner.runSequentially(SuiteRunner.java:382)
	at org.testng.SuiteRunner.privateRun(SuiteRunner.java:340)
	at org.testng.SuiteRunner.run(SuiteRunner.java:289)
	at org.testng.SuiteRunnerWorker.runSuite(SuiteRunnerWorker.java:52)
	at org.testng.SuiteRunnerWorker.run(SuiteRunnerWorker.java:86)
	at org.testng.TestNG.runSuitesSequentially(TestNG.java:1293)
	at org.testng.TestNG.runSuitesLocally(TestNG.java:1218)
	at org.testng.TestNG.runSuites(TestNG.java:1133)
	at org.testng.TestNG.run(TestNG.java:1104)
	at org.apache.maven.surefire.testng.TestNGExecutor.run(TestNGExecutor.java:284)
	at org.apache.maven.surefire.testng.TestNGXmlTestSuite.execute(TestNGXmlTestSuite.java:75)
	at org.apache.maven.surefire.testng.TestNGProvider.invoke(TestNGProvider.java:119)
	at org.apache.maven.surefire.booter.ForkedBooter.runSuitesInProcess(ForkedBooter.java:428)
	at org.apache.maven.surefire.booter.ForkedBooter.execute(ForkedBooter.java:162)
	at org.apache.maven.surefire.booter.ForkedBooter.run(ForkedBooter.java:562)
	at org.apache.maven.surefire.booter.ForkedBooter.main(ForkedBooter.java:548)
]]>
    </failure>
  </testcase> <!-- testMethod2 -->
  <testcase name="testMethod1" time="0.002" classname="com.TestNGproject.TestNGAssertsDemo"/>
</testsuite> <!-- com.TestNGproject.TestNGAssertsDemo -->
